Workbook

Sheet Assumptions
A1: CustomerPulse AI — Financial Model Assumptions
A2: Marketing Analyst — Orbitel
A4: Investment Costs
A5: Development Cost (Rs.) | B5: 1500000
A6: Cloud Infrastructure Setup (Rs.) | B6: 300000
A7: Annual Maintenance (Rs.) | B7: 100000
A8: Amortization Period (Years) | B8: 5
A9: Monthly Amortized Investment (Rs.) | B9: =(B5+B6)/(B8*12) -> 30000
A10: Monthly Maintenance (Rs.) | B10: =B7/12 -> 8333.3333
A11: Total Monthly Fixed Cost (Rs.) | B11: =B9+B10 -> 38333.333
A13: Per-Client Variable Costs
A14: CAC per Client (Rs.) | B14: 575
A15: Onboarding Cost per Client (Rs.) | B15: 1850
A16: Support Cost per Client/Month (Rs.) | B16: 1200
A17: Total Acquisition Cost per Client (Rs.) | B17: =B14+B15 -> 2425
A19: Pricing Strategy (Rs./Month) | B19: Base Price | C19: Target Segment
A20: Starter Plan | B20: 3999 | C20: Solo Entrepreneurs
A21: Growth Plan | B21: 7999 | C21: Small Teams / Agencies
A22: Pro Plan | B22: 14999 | C22: Multi-brand Businesses
A24: Demand & Growth Assumptions | B24: Starter | C24: Growth | D24: Pro
A25: Base Demand (Clients) | B25: 1200 | C25: 800 | D25: 400
A26: Monthly Net Growth Rate | B26: 0.1 | C26: 0.08 | D26: 0.05
A28: Price Sensitivity Parameters | B28: Starter | C28: Growth | D28: Pro
A29: Price Change % | B29: 0 | C29: 0 | D29: 0
A30: Demand Elasticity (per 10% price ↑) | B30: -0.1 | C30: -0.05 | D30: -0.025
A31: Effective Price (Rs./Month) | B31: =B20*(1+B29) -> 3999 | C31: =B21*(1+C29) -> 7999 | D31: =B22*(1+D29) -> 14999
A32: Adjusted Base Demand | B32: =B25*(1+(B29/0.1)*B30) -> 1200 | C32: =C25*(1+(C29/0.1)*C30) -> 800 | D32: =D25*(1+(D29/0.1)*D30) -> 400
A34: Opportunity Cost Estimates | B34: Amount (Rs.) | C34: Notes
A35: Client Projects | B35: 1000000 | C35: 4 developers × 6 months
A36: Bank Investment | B36: 800000 | C36: 8% return on investment
A37: AI Chatbot Expansion | B37: 700000 | C37: 15% ROI
A38: Total Opportunity Cost (Rs.) | B38: =SUM(B35:B37) -> 2500000

Sheet Monthly Model
A1: CustomerPulse AI — 12-Month Financial Projections
A2: Marketing Analyst — Orbitel
A4: Metric | B4: Month 1 | C4: Month 2 | D4: Month 3 | E4: Month 4 | F4: Month 5 | G4: Month 6 | H4: Month 7 | I4: Month 8 | J4: Month 9 | K4: Month 10 | L4: Month 11 | M4: Month 12
A5: STARTER TIER
A6: Subscribers | B6: =Assumptions!B32 -> 1200 | C6: =B6*(1+Assumptions!$B$26) -> 1320 | D6: =C6*(1+Assumptions!$B$26) -> 1452 | E6: =D6*(1+Assumptions!$B$26) -> 1597.2 | F6: =E6*(1+Assumptions!$B$26) -> 1756.92 | G6: =F6*(1+Assumptions!$B$26) -> 1932.612 | H6: =G6*(1+Assumptions!$B$26) -> 2125.8732 | I6: =H6*(1+Assumptions!$B$26) -> 2338.4605 | J6: =I6*(1+Assumptions!$B$26) -> 2572.3066 | ... M6: =L6*(1+Assumptions!$B$26) -> 3423.74
A7: New Clients | B7: =B6 -> 1200 | C7: =C6-B6 -> 120 | D7: =D6-C6 -> 132 | E7: =E6-D6 -> 145.2 | F7: =F6-E6 -> 159.72 | G7: =G6-F6 -> 175.692 | H7: =H6-G6 -> 193.2612 | I7: =I6-H6 -> 212.58732 | J7: =J6-I6 -> 233.84605 | ... M7: =M6-L6 -> 311.2491
A8: Revenue (Rs.) | B8: =B6*Assumptions!$B$31 -> 4798800 | C8: =C6*Assumptions!$B$31 -> 5278680 | D8: =D6*Assumptions!$B$31 -> 5806548 | E8: =E6*Assumptions!$B$31 -> 6387202.8 | F8: =F6*Assumptions!$B$31 -> 7025923.1 | G8: =G6*Assumptions!$B$31 -> 7728515.4 | H8: =H6*Assumptions!$B$31 -> 8501366.9 | I8: =I6*Assumptions!$B$31 -> 9351503.6 | ... M8: =M6*Assumptions!$B$31 -> 13691536
A9: Support Cost (Rs.) | B9: =B6*Assumptions!$B$16 -> 1440000 | C9: =C6*Assumptions!$B$16 -> 1584000 | D9: =D6*Assumptions!$B$16 -> 1742400 | E9: =E6*Assumptions!$B$16 -> 1916640 | F9: =F6*Assumptions!$B$16 -> 2108304 | G9: =G6*Assumptions!$B$16 -> 2319134.4 | H9: =H6*Assumptions!$B$16 -> 2551047.8 | I9: =I6*Assumptions!$B$16 -> 2806152.6 | ... M9: =M6*Assumptions!$B$16 -> 4108488.1
A10: Acquisition Cost (Rs.) | B10: =B7*Assumptions!$B$17 -> 2910000 | C10: =C7*Assumptions!$B$17 -> 291000 | D10: =D7*Assumptions!$B$17 -> 320100 | E10: =E7*Assumptions!$B$17 -> 352110 | F10: =F7*Assumptions!$B$17 -> 387321 | G10: =G7*Assumptions!$B$17 -> 426053.1 | H10: =H7*Assumptions!$B$17 -> 468658.41 | I10: =I7*Assumptions!$B$17 -> 515524.25 | ... M10: =M7*Assumptions!$B$17 -> 754779.06
A11: Fixed Cost — 1/3 Alloc (Rs.) | B11: =Assumptions!$B$11/3 -> 12777.778 | C11: =Assumptions!$B$11/3 -> 12777.778 | D11: =Assumptions!$B$11/3 -> 12777.778 | E11: =Assumptions!$B$11/3 -> 12777.778 | F11: =Assumptions!$B$11/3 -> 12777.778 | G11: =Assumptions!$B$11/3 -> 12777.778 | H11: =Assumptions!$B$11/3 -> 12777.778 | I11: =Assumptions!$B$11/3 -> 12777.778 | ... M11: =Assumptions!$B$11/3 -> 12777.778
A12: Total Cost (Rs.) | B12: =SUM(B9:B11) -> 4362777.8 | C12: =SUM(C9:C11) -> 1887777.8 | D12: =SUM(D9:D11) -> 2075277.8 | E12: =SUM(E9:E11) -> 2281527.8 | F12: =SUM(F9:F11) -> 2508402.8 | G12: =SUM(G9:G11) -> 2757965.3 | H12: =SUM(H9:H11) -> 3032484 | I12: =SUM(I9:I11) -> 3334454.7 | ... M12: =SUM(M9:M11) -> 4876044.9
A13: Gross Profit (Rs.) | B13: =B8-B12 -> 436022.22 | C13: =C8-C12 -> 3390902.2 | D13: =D8-D12 -> 3731270.2 | E13: =E8-E12 -> 4105675 | F13: =F8-F12 -> 4517520.3 | G13: =G8-G12 -> 4970550.1 | H13: =H8-H12 -> 5468882.9 | I13: =I8-I12 -> 6017049 | ... M13: =M8-M12 -> 8815491.6
A14: Profit Margin (%) | B14: =IF(B8=0,0,B13/B8) -> 0.090860678 | C14: =IF(C8=0,0,C13/C8) -> 0.64237692 | D14: =IF(D8=0,0,D13/D8) -> 0.64259698 | E14: =IF(E8=0,0,E13/E8) -> 0.64279704 | F14: =IF(F8=0,0,F13/F8) -> 0.6429789 | G14: =IF(G8=0,0,G13/G8) -> 0.64314423 | H14: =IF(H8=0,0,H13/H8) -> 0.64329454 | I14: =IF(I8=0,0,I13/I8) -> 0.64343118 | ... M14: =IF(M8=0,0,M13/M8) -> 0.6438643
A16: GROWTH TIER
A17: Subscribers | B17: =Assumptions!C32 -> 800 | C17: =B17*(1+Assumptions!$C$26) -> 864 | D17: =C17*(1+Assumptions!$C$26) -> 933.12 | E17: =D17*(1+Assumptions!$C$26) -> 1007.7696 | F17: =E17*(1+Assumptions!$C$26) -> 1088.3912 | G17: =F17*(1+Assumptions!$C$26) -> 1175.4625 | H17: =G17*(1+Assumptions!$C$26) -> 1269.4995 | I17: =H17*(1+Assumptions!$C$26) -> 1371.0594 | J17: =I17*(1+Assumptions!$C$26) -> 1480.7442 | ... M17: =L17*(1+Assumptions!$C$26) -> 1865.3112
A18: New Clients | B18: =B17 -> 800 | C18: =C17-B17 -> 64 | D18: =D17-C17 -> 69.12 | E18: =E17-D17 -> 74.6496 | F18: =F17-E17 -> 80.621568 | G18: =G17-F17 -> 87.071293 | H18: =H17-G17 -> 94.036997 | I18: =I17-H17 -> 101.55996 | J18: =J17-I17 -> 109.68475 | ... M18: =M17-L17 -> 138.1712
A19: Revenue (Rs.) | B19: =B17*Assumptions!$C$31 -> 6399200 | C19: =C17*Assumptions!$C$31 -> 6911136 | D19: =D17*Assumptions!$C$31 -> 7464026.9 | E19: =E17*Assumptions!$C$31 -> 8061149 | F19: =F17*Assumptions!$C$31 -> 8706041 | G19: =G17*Assumptions!$C$31 -> 9402524.2 | H19: =H17*Assumptions!$C$31 -> 10154726 | I19: =I17*Assumptions!$C$31 -> 10967104 | ... M19: =M17*Assumptions!$C$31 -> 14920624
A20: Support Cost (Rs.) | B20: =B17*Assumptions!$B$16 -> 960000 | C20: =C17*Assumptions!$B$16 -> 1036800 | D20: =D17*Assumptions!$B$16 -> 1119744 | E20: =E17*Assumptions!$B$16 -> 1209323.5 | F20: =F17*Assumptions!$B$16 -> 1306069.4 | G20: =G17*Assumptions!$B$16 -> 1410555 | H20: =H17*Assumptions!$B$16 -> 1523399.4 | I20: =I17*Assumptions!$B$16 -> 1645271.3 | ... M20: =M17*Assumptions!$B$16 -> 2238373.4
A21: Acquisition Cost (Rs.) | B21: =B18*Assumptions!$B$17 -> 1940000 | C21: =C18*Assumptions!$B$17 -> 155200 | D21: =D18*Assumptions!$B$17 -> 167616 | E21: =E18*Assumptions!$B$17 -> 181025.28 | F21: =F18*Assumptions!$B$17 -> 195507.3 | G21: =G18*Assumptions!$B$17 -> 211147.89 | H21: =H18*Assumptions!$B$17 -> 228039.72 | I21: =I18*Assumptions!$B$17 -> 246282.89 | ... M21: =M18*Assumptions!$B$17 -> 335065.16
A22: Fixed Cost — 1/3 Alloc (Rs.) | B22: =Assumptions!$B$11/3 -> 12777.778 | C22: =Assumptions!$B$11/3 -> 12777.778 | D22: =Assumptions!$B$11/3 -> 12777.778 | E22: =Assumptions!$B$11/3 -> 12777.778 | F22: =Assumptions!$B$11/3 -> 12777.778 | G22: =Assumptions!$B$11/3 -> 12777.778 | H22: =Assumptions!$B$11/3 -> 12777.778 | I22: =Assumptions!$B$11/3 -> 12777.778 | ... M22: =Assumptions!$B$11/3 -> 12777.778
A23: Total Cost (Rs.) | B23: =SUM(B20:B22) -> 2912777.8 | C23: =SUM(C20:C22) -> 1204777.8 | D23: =SUM(D20:D22) -> 1300137.8 | E23: =SUM(E20:E22) -> 1403126.6 | F23: =SUM(F20:F22) -> 1514354.5 | G23: =SUM(G20:G22) -> 1634480.6 | H23: =SUM(H20:H22) -> 1764216.8 | I23: =SUM(I20:I22) -> 1904332 | ... M23: =SUM(M20:M22) -> 2586216.4
A24: Gross Profit (Rs.) | B24: =B19-B23 -> 3486422.2 | C24: =C19-C23 -> 5706358.2 | D24: =D19-D23 -> 6163889.1 | E24: =E19-E23 -> 6658022.5 | F24: =F19-F23 -> 7191686.5 | G24: =G19-G23 -> 7768043.6 | H24: =H19-H23 -> 8390509.3 | I24: =I19-I23 -> 9062772.3 | ... M24: =M19-M23 -> 12334408
A25: Profit Margin (%) | B25: =IF(B19=0,0,B24/B19) -> 0.54482157 | C25: =IF(C19=0,0,C24/C19) -> 0.82567587 | D25: =IF(D19=0,0,D24/D19) -> 0.82581282 | E25: =IF(E19=0,0,E24/E19) -> 0.82593963 | F25: =IF(F19=0,0,F24/F19) -> 0.82605705 | G25: =IF(G19=0,0,G24/G19) -> 0.82616576 | H25: =IF(H19=0,0,H24/H19) -> 0.82626643 | I25: =IF(I19=0,0,I24/I19) -> 0.82635964 | ... M25: =IF(M19=0,0,M24/M19) -> 0.82666835
A27: PRO TIER
A28: Subscribers | B28: =Assumptions!D32 -> 400 | C28: =B28*(1+Assumptions!$D$26) -> 420 | D28: =C28*(1+Assumptions!$D$26) -> 441 | E28: =D28*(1+Assumptions!$D$26) -> 463.05 | F28: =E28*(1+Assumptions!$D$26) -> 486.2025 | G28: =F28*(1+Assumptions!$D$26) -> 510.51263 | H28: =G28*(1+Assumptions!$D$26) -> 536.03826 | I28: =H28*(1+Assumptions!$D$26) -> 562.84017 | J28: =I28*(1+Assumptions!$D$26) -> 590.98218 | ... M28: =L28*(1+Assumptions!$D$26) -> 684.13574
A29: New Clients | B29: =B28 -> 400 | C29: =C28-B28 -> 20 | D29: =D28-C28 -> 21 | E29: =E28-D28 -> 22.05 | F29: =F28-E28 -> 23.1525 | G29: =G28-F28 -> 24.310125 | H29: =H28-G28 -> 25.525631 | I29: =I28-H28 -> 26.801913 | J29: =J28-I28 -> 28.142008 | ... M29: =M28-L28 -> 32.577893
A30: Revenue (Rs.) | B30: =B28*Assumptions!$D$31 -> 5999600 | C30: =C28*Assumptions!$D$31 -> 6299580 | D30: =D28*Assumptions!$D$31 -> 6614559 | E30: =E28*Assumptions!$D$31 -> 6945287 | F30: =F28*Assumptions!$D$31 -> 7292551.3 | G30: =G28*Assumptions!$D$31 -> 7657178.9 | H30: =H28*Assumptions!$D$31 -> 8040037.8 | I30: =I28*Assumptions!$D$31 -> 8442039.7 | ... M30: =M28*Assumptions!$D$31 -> 10261352
A31: Support Cost (Rs.) | B31: =B28*Assumptions!$B$16 -> 480000 | C31: =C28*Assumptions!$B$16 -> 504000 | D31: =D28*Assumptions!$B$16 -> 529200 | E31: =E28*Assumptions!$B$16 -> 555660 | F31: =F28*Assumptions!$B$16 -> 583443 | G31: =G28*Assumptions!$B$16 -> 612615.15 | H31: =H28*Assumptions!$B$16 -> 643245.91 | I31: =I28*Assumptions!$B$16 -> 675408.2 | ... M31: =M28*Assumptions!$B$16 -> 820962.89
A32: Acquisition Cost (Rs.) | B32: =B29*Assumptions!$B$17 -> 970000 | C32: =C29*Assumptions!$B$17 -> 48500 | D32: =D29*Assumptions!$B$17 -> 50925 | E32: =E29*Assumptions!$B$17 -> 53471.25 | F32: =F29*Assumptions!$B$17 -> 56144.813 | G32: =G29*Assumptions!$B$17 -> 58952.053 | H32: =H29*Assumptions!$B$17 -> 61899.656 | I32: =I29*Assumptions!$B$17 -> 64994.639 | ... M32: =M29*Assumptions!$B$17 -> 79001.389
A33: Fixed Cost — 1/3 Alloc (Rs.) | B33: =Assumptions!$B$11/3 -> 12777.778 | C33: =Assumptions!$B$11/3 -> 12777.778 | D33: =Assumptions!$B$11/3 -> 12777.778 | E33: =Assumptions!$B$11/3 -> 12777.778 | F33: =Assumptions!$B$11/3 -> 12777.778 | G33: =Assumptions!$B$11/3 -> 12777.778 | H33: =Assumptions!$B$11/3 -> 12777.778 | I33: =Assumptions!$B$11/3 -> 12777.778 | ... M33: =Assumptions!$B$11/3 -> 12777.778
A34: Total Cost (Rs.) | B34: =SUM(B31:B33) -> 1462777.8 | C34: =SUM(C31:C33) -> 565277.78 | D34: =SUM(D31:D33) -> 592902.78 | E34: =SUM(E31:E33) -> 621909.03 | F34: =SUM(F31:F33) -> 652365.59 | G34: =SUM(G31:G33) -> 684344.98 | H34: =SUM(H31:H33) -> 717923.34 | I34: =SUM(I31:I33) -> 753180.62 | ... M34: =SUM(M31:M33) -> 912742.06
A35: Gross Profit (Rs.) | B35: =B30-B34 -> 4536822.2 | C35: =C30-C34 -> 5734302.2 | D35: =D30-D34 -> 6021656.2 | E35: =E30-E34 -> 6323377.9 | F35: =F30-F34 -> 6640185.7 | G35: =G30-G34 -> 6972833.9 | H35: =H30-H34 -> 7322114.5 | I35: =I30-I34 -> 7688859.1 | ... M35: =M30-M34 -> 9348610
A36: Profit Margin (%) | B36: =IF(B30=0,0,B35/B30) -> 0.75618745 | C36: =IF(C30=0,0,C35/C30) -> 0.91026739 | D36: =IF(D30=0,0,D35/D30) -> 0.91036397 | E36: =IF(E30=0,0,E35/E30) -> 0.91045596 | F36: =IF(F30=0,0,F35/F30) -> 0.91054357 | G36: =IF(G30=0,0,G35/G30) -> 0.91062701 | H36: =IF(H30=0,0,H35/H30) -> 0.91070647 | I36: =IF(I30=0,0,I35/I30) -> 0.91078215 | ... M36: =IF(M30=0,0,M35/M30) -> 0.91105051
A38: CONSOLIDATED — ALL TIERS
A39: Total Subscribers | B39: =B6+B17+B28 -> 2400 | C39: =C6+C17+C28 -> 2604 | D39: =D6+D17+D28 -> 2826.12 | E39: =E6+E17+E28 -> 3068.0196 | F39: =F6+F17+F28 -> 3331.5137 | G39: =G6+G17+G28 -> 3618.5871 | H39: =H6+H17+H28 -> 3931.4109 | I39: =I6+I17+I28 -> 4272.3601 | ... M39: =M6+M17+M28 -> 5973.187
A40: Total New Clients | B40: =B7+B18+B29 -> 2400 | C40: =C7+C18+C29 -> 204 | D40: =D7+D18+D29 -> 222.12 | E40: =E7+E18+E29 -> 241.8996 | F40: =F7+F18+F29 -> 263.49407 | G40: =G7+G18+G29 -> 287.07342 | H40: =H7+H18+H29 -> 312.82383 | I40: =I7+I18+I29 -> 340.94919 | ... M40: =M7+M18+M29 -> 481.99819
A41: Total Revenue (Rs.) | B41: =B8+B19+B30 -> 17197600 | C41: =C8+C19+C30 -> 18489396 | D41: =D8+D19+D30 -> 19885134 | E41: =E8+E19+E30 -> 21393639 | F41: =F8+F19+F30 -> 23024515 | G41: =G8+G19+G30 -> 24788218 | H41: =H8+H19+H30 -> 26696131 | I41: =I8+I19+I30 -> 28760648 | ... M41: =M8+M19+M30 -> 38873513
A42: Total Support Cost (Rs.) | B42: =B9+B20+B31 -> 2880000 | C42: =C9+C20+C31 -> 3124800 | D42: =D9+D20+D31 -> 3391344 | E42: =E9+E20+E31 -> 3681623.5 | F42: =F9+F20+F31 -> 3997816.4 | G42: =G9+G20+G31 -> 4342304.5 | H42: =H9+H20+H31 -> 4717693.1 | I42: =I9+I20+I31 -> 5126832.1 | ... M42: =M9+M20+M31 -> 7167824.4
A43: Total Acquisition Cost (Rs.) | B43: =B10+B21+B32 -> 5820000 | C43: =C10+C21+C32 -> 494700 | D43: =D10+D21+D32 -> 538641 | E43: =E10+E21+E32 -> 586606.53 | F43: =F10+F21+F32 -> 638973.11 | G43: =G10+G21+G32 -> 696153.04 | H43: =H10+H21+H32 -> 758597.78 | I43: =I10+I21+I32 -> 826801.78 | ... M43: =M10+M21+M32 -> 1168845.6
A44: Total Fixed Cost (Rs.) | B44: =Assumptions!$B$11 -> 38333.333 | C44: =Assumptions!$B$11 -> 38333.333 | D44: =Assumptions!$B$11 -> 38333.333 | E44: =Assumptions!$B$11 -> 38333.333 | F44: =Assumptions!$B$11 -> 38333.333 | G44: =Assumptions!$B$11 -> 38333.333 | H44: =Assumptions!$B$11 -> 38333.333 | I44: =Assumptions!$B$11 -> 38333.333 | ... M44: =Assumptions!$B$11 -> 38333.333
...

Sheet Scenario Analysis
A1: Scenario Analysis — What-If Comparison
A2: Compare Base, Optimistic, and Pessimistic Scenarios
A4: Scenario Parameters | B4: Base Case | C4: Optimistic | D4: Pessimistic
A5: Starter — Base Demand | B5: =Assumptions!B25 -> 1200 | C5: =B5*1.2 -> 1440 | D5: =B5*0.75 -> 900
A6: Starter — Growth Rate | B6: =Assumptions!B26 -> 0.1 | C6: 0.15 | D6: 0.05
A7: Starter — Price (Rs.) | B7: =Assumptions!B20 -> 3999 | C7: =B7 -> 3999 | D7: =B7*0.85 -> 3399.15
A8: Growth — Base Demand | B8: =Assumptions!C25 -> 800 | C8: =B8*1.2 -> 960 | D8: =B8*0.75 -> 600
A9: Growth — Growth Rate | B9: =Assumptions!C26 -> 0.08 | C9: 0.12 | D9: 0.04
A10: Growth — Price (Rs.) | B10: =Assumptions!B21 -> 7999 | C10: =B10 -> 7999 | D10: =B10*0.85 -> 6799.15
A11: Pro — Base Demand | B11: =Assumptions!D25 -> 400 | C11: =B11*1.15 -> 460 | D11: =B11*0.7 -> 280
A12: Pro — Growth Rate | B12: =Assumptions!D26 -> 0.05 | C12: 0.08 | D12: 0.02
A13: Pro — Price (Rs.) | B13: =Assumptions!B22 -> 14999 | C13: =B13 -> 14999 | D13: =B13*0.85 -> 12749.15
A15: Pessimistic — 12-Month Output
A16: Starter — Month 12 Subscribers | B16: =B5*(1+B6)^11 -> 3423.74 | C16: =C5*(1+C6)^11 -> 6699.4436 | D16: =D5*(1+D6)^11 -> 1539.3054
A17: Growth — Month 12 Subscribers | B17: =B8*(1+B9)^11 -> 1865.3112 | C17: =C8*(1+C9)^11 -> 3339.408 | D17: =D8*(1+D9)^11 -> 923.67243
A18: Pro — Month 12 Subscribers | B18: =B11*(1+B12)^11 -> 684.13574 | C18: =C11*(1+C12)^11 -> 1072.5539 | D18: =D11*(1+D12)^11 -> 348.14481
A19: Total Month 12 Subscribers | B19: =SUM(B16:B18) -> 5973.187 | C19: =SUM(C16:C18) -> 11111.406 | D19: =SUM(D16:D18) -> 2811.1227
A20: 12-Month Total Revenue (Rs.) | B20: =B5*B7*IF(B6=0,12,((1+B6)^12-1)/B6)+B8*B10*IF(B9=0,12,((1+B9)^12-1)/B9)+B11*B13*IF(B12=0,12,((1+B12)^12-1)/B12) -> 3.1955372e+08 | C20: =C5*C7*IF(C6=0,12,((1+C6)^12-1)/C6)+C8*C10*IF(C9=0,12,((1+C9)^12-1)/C9)+C11*C13*IF(C12=0,12,((1+C12)^12-1)/C12) -> 4.8326058e+08 | D20: =D5*D7*IF(D6=0,12,((1+D6)^12-1)/D6)+D8*D10*IF(D9=0,12,((1+D9)^12-1)/D9)+D11*D13*IF(D12=0,12,((1+D12)^12-1)/D12) -> 1.5786982e+08
A21: 12-Month Total Cost (Rs.) | B21: =Assumptions!$B$16*(B5*IF(B6=0,12,((1+B6)^12-1)/B6)+B8*IF(B9=0,12,((1+B9)^12-1)/B9)+B11*IF(B12=0,12,((1+B12)^12-1)/B12))+Assumptions!$B$17*(B5*(1+B6)^11+B8*(1+B9)^11+B11*(1+B12)^11)+Assumptions!$B$11*12 -> 71596609 | C21: =Assumptions!$B$16*(C5*IF(C6=0,12,((1+C6)^12-1)/C6)+C8*IF(C9=0,12,((1+C9)^12-1)/C9)+C11*IF(C12=0,12,((1+C12)^12-1)/C12))+Assumptions!$B$17*(C5*(1+C6)^11+C8*(1+C9)^11+C11*(1+C12)^11)+Assumptions!$B$11*12 -> 1.1579678e+08 | D21: =Assumptions!$B$16*(D5*IF(D6=0,12,((1+D6)^12-1)/D6)+D8*IF(D9=0,12,((1+D9)^12-1)/D9)+D11*IF(D12=0,12,((1+D12)^12-1)/D12))+Assumptions!$B$17*(D5*(1+D6)^11+D8*(1+D9)^11+D11*(1+D12)^11)+Assumptions!$B$11*12 -> 39792511
A22: 12-Month Total Profit (Rs.) | B22: =B20-B21 -> 2.4795711e+08 | C22: =C20-C21 -> 3.674638e+08 | D22: =D20-D21 -> 1.1807731e+08
A23: Profit Margin (%) | B23: =IF(B20=0,0,B22/B20) -> 0.77594813 | C23: =IF(C20=0,0,C22/C20) -> 0.76038438 | D23: =IF(D20=0,0,D22/D20) -> 0.74794099
A24: Profit vs Opportunity Cost | B24: =B22-Assumptions!$B$38 -> 2.4545711e+08 | C24: =C22-Assumptions!$B$38 -> 3.649638e+08 | D24: =D22-Assumptions!$B$38 -> 1.1557731e+08

Sheet Price Sensitivity
A1: Price Sensitivity Analysis — Impact on 12-Month Profit
A2: Shows how price changes affect demand and profitability per tier
A4: Price Change Scenario | B4: Starter Eff. Price | C4: Starter Adj. Demand | D4: Growth Eff. Price | E4: Growth Adj. Demand | F4: Pro Eff. Price | G4: Pro Adj. Demand | H4: 12-Mo Total Revenue | I4: 12-Mo Total Cost | J4: 12-Mo Total Profit | K4: Profit Margin
A5: -0.2 | B5: =Assumptions!B20*(1+A5) -> 3199.2 | C5: =Assumptions!B25*(1+(A5/0.1)*Assumptions!B30) -> 1440 | D5: =Assumptions!B21*(1+A5) -> 6399.2 | E5: =Assumptions!C25*(1+(A5/0.1)*Assumptions!C30) -> 880 | F5: =Assumptions!B22*(1+A5) -> 11999.2 | G5: =Assumptions!D25*(1+(A5/0.1)*Assumptions!D30) -> 420 | H5: =C5*B5*IF(Assumptions!$B$26=0,12,((1+Assumptions!$B$26)^12-1)/Assumptions!$B$26)+E5*D5*IF(Assumptions!$C$26=0,12,((1+Assumptions!$C$26)^12-1)/Assumptions!$C$26)+G5*F5*IF(Assumptions!$D$26=0,12,((1+Assumptions!$D$26)^12-1)/Assumptions!$D$26) -> 2.8559693e+08 | I5: =Assumptions!$B$16*(C5*IF(Assumptions!$B$26=0,12,((1+Assumptions!$B$26)^12-1)/Assumptions!$B$26)+E5*IF(Assumptions!$C$26=0,12,((1+Assumptions!$C$26)^12-1)/Assumptions!$C$26)+G5*IF(Assumptions!$D$26=0,12,((1+Assumptions!$D$26)^12-1)/Assumptions!$D$26))+Assumptions!$B$17*(C5*(1+Assumptions!$B$26)^11+E5*(1+Assumptions!$C$26)^11+G5*(1+Assumptions!$D$26)^11)+Assumptions!$B$11*12 -> 82154901 | J5: =H5-I5 -> 2.0344203e+08 | K5: =IF(H5=0,0,J5/H5) -> 0.71233969
A6: -0.15 | B6: =Assumptions!B20*(1+A6) -> 3399.15 | C6: =Assumptions!B25*(1+(A6/0.1)*Assumptions!B30) -> 1380 | D6: =Assumptions!B21*(1+A6) -> 6799.15 | E6: =Assumptions!C25*(1+(A6/0.1)*Assumptions!C30) -> 860 | F6: =Assumptions!B22*(1+A6) -> 12749.15 | G6: =Assumptions!D25*(1+(A6/0.1)*Assumptions!D30) -> 415 | H6: =C6*B6*IF(Assumptions!$B$26=0,12,((1+Assumptions!$B$26)^12-1)/Assumptions!$B$26)+E6*D6*IF(Assumptions!$C$26=0,12,((1+Assumptions!$C$26)^12-1)/Assumptions!$C$26)+G6*F6*IF(Assumptions!$D$26=0,12,((1+Assumptions!$D$26)^12-1)/Assumptions!$D$26) -> 2.9549022e+08 | I6: =Assumptions!$B$16*(C6*IF(Assumptions!$B$26=0,12,((1+Assumptions!$B$26)^12-1)/Assumptions!$B$26)+E6*IF(Assumptions!$C$26=0,12,((1+Assumptions!$C$26)^12-1)/Assumptions!$C$26)+G6*IF(Assumptions!$D$26=0,12,((1+Assumptions!$D$26)^12-1)/Assumptions!$D$26))+Assumptions!$B$17*(C6*(1+Assumptions!$B$26)^11+E6*(1+Assumptions!$C$26)^11+G6*(1+Assumptions!$D$26)^11)+Assumptions!$B$11*12 -> 79515328 | J6: =H6-I6 -> 2.1597489e+08 | K6: =IF(H6=0,0,J6/H6) -> 0.73090369
A7: -0.1 | B7: =Assumptions!B20*(1+A7) -> 3599.1 | C7: =Assumptions!B25*(1+(A7/0.1)*Assumptions!B30) -> 1320 | D7: =Assumptions!B21*(1+A7) -> 7199.1 | E7: =Assumptions!C25*(1+(A7/0.1)*Assumptions!C30) -> 840 | F7: =Assumptions!B22*(1+A7) -> 13499.1 | G7: =Assumptions!D25*(1+(A7/0.1)*Assumptions!D30) -> 410 | H7: =C7*B7*IF(Assumptions!$B$26=0,12,((1+Assumptions!$B$26)^12-1)/Assumptions!$B$26)+E7*D7*IF(Assumptions!$C$26=0,12,((1+Assumptions!$C$26)^12-1)/Assumptions!$C$26)+G7*F7*IF(Assumptions!$D$26=0,12,((1+Assumptions!$D$26)^12-1)/Assumptions!$D$26) -> 3.0444745e+08 | I7: =Assumptions!$B$16*(C7*IF(Assumptions!$B$26=0,12,((1+Assumptions!$B$26)^12-1)/Assumptions!$B$26)+E7*IF(Assumptions!$C$26=0,12,((1+Assumptions!$C$26)^12-1)/Assumptions!$C$26)+G7*IF(Assumptions!$D$26=0,12,((1+Assumptions!$D$26)^12-1)/Assumptions!$D$26))+Assumptions!$B$17*(C7*(1+Assumptions!$B$26)^11+E7*(1+Assumptions!$C$26)^11+G7*(1+Assumptions!$D$26)^11)+Assumptions!$B$11*12 -> 76875755 | J7: =H7-I7 -> 2.2757169e+08 | K7: =IF(H7=0,0,J7/H7) -> 0.74749089
A8: -0.05 | B8: =Assumptions!B20*(1+A8) -> 3799.05 | C8: =Assumptions!B25*(1+(A8/0.1)*Assumptions!B30) -> 1260 | D8: =Assumptions!B21*(1+A8) -> 7599.05 | E8: =Assumptions!C25*(1+(A8/0.1)*Assumptions!C30) -> 820 | F8: =Assumptions!B22*(1+A8) -> 14249.05 | G8: =Assumptions!D25*(1+(A8/0.1)*Assumptions!D30) -> 405 | H8: =C8*B8*IF(Assumptions!$B$26=0,12,((1+Assumptions!$B$26)^12-1)/Assumptions!$B$26)+E8*D8*IF(Assumptions!$C$26=0,12,((1+Assumptions!$C$26)^12-1)/Assumptions!$C$26)+G8*F8*IF(Assumptions!$D$26=0,12,((1+Assumptions!$D$26)^12-1)/Assumptions!$D$26) -> 3.1246861e+08 | I8: =Assumptions!$B$16*(C8*IF(Assumptions!$B$26=0,12,((1+Assumptions!$B$26)^12-1)/Assumptions!$B$26)+E8*IF(Assumptions!$C$26=0,12,((1+Assumptions!$C$26)^12-1)/Assumptions!$C$26)+G8*IF(Assumptions!$D$26=0,12,((1+Assumptions!$D$26)^12-1)/Assumptions!$D$26))+Assumptions!$B$17*(C8*(1+Assumptions!$B$26)^11+E8*(1+Assumptions!$C$26)^11+G8*(1+Assumptions!$D$26)^11)+Assumptions!$B$11*12 -> 74236182 | J8: =H8-I8 -> 2.3823243e+08 | K8: =IF(H8=0,0,J8/H8) -> 0.76242036
A9: 0 | B9: =Assumptions!B20*(1+A9) -> 3999 | C9: =Assumptions!B25*(1+(A9/0.1)*Assumptions!B30) -> 1200 | D9: =Assumptions!B21*(1+A9) -> 7999 | E9: =Assumptions!C25*(1+(A9/0.1)*Assumptions!C30) -> 800 | F9: =Assumptions!B22*(1+A9) -> 14999 | G9: =Assumptions!D25*(1+(A9/0.1)*Assumptions!D30) -> 400 | H9: =C9*B9*IF(Assumptions!$B$26=0,12,((1+Assumptions!$B$26)^12-1)/Assumptions!$B$26)+E9*D9*IF(Assumptions!$C$26=0,12,((1+Assumptions!$C$26)^12-1)/Assumptions!$C$26)+G9*F9*IF(Assumptions!$D$26=0,12,((1+Assumptions!$D$26)^12-1)/Assumptions!$D$26) -> 3.1955372e+08 | I9: =Assumptions!$B$16*(C9*IF(Assumptions!$B$26=0,12,((1+Assumptions!$B$26)^12-1)/Assumptions!$B$26)+E9*IF(Assumptions!$C$26=0,12,((1+Assumptions!$C$26)^12-1)/Assumptions!$C$26)+G9*IF(Assumptions!$D$26=0,12,((1+Assumptions!$D$26)^12-1)/Assumptions!$D$26))+Assumptions!$B$17*(C9*(1+Assumptions!$B$26)^11+E9*(1+Assumptions!$C$26)^11+G9*(1+Assumptions!$D$26)^11)+Assumptions!$B$11*12 -> 71596609 | J9: =H9-I9 -> 2.4795711e+08 | K9: =IF(H9=0,0,J9/H9) -> 0.77594813
A10: 0.05 | B10: =Assumptions!B20*(1+A10) -> 4198.95 | C10: =Assumptions!B25*(1+(A10/0.1)*Assumptions!B30) -> 1140 | D10: =Assumptions!B21*(1+A10) -> 8398.95 | E10: =Assumptions!C25*(1+(A10/0.1)*Assumptions!C30) -> 780 | F10: =Assumptions!B22*(1+A10) -> 15748.95 | G10: =Assumptions!D25*(1+(A10/0.1)*Assumptions!D30) -> 395 | H10: =C10*B10*IF(Assumptions!$B$26=0,12,((1+Assumptions!$B$26)^12-1)/Assumptions!$B$26)+E10*D10*IF(Assumptions!$C$26=0,12,((1+Assumptions!$C$26)^12-1)/Assumptions!$C$26)+G10*F10*IF(Assumptions!$D$26=0,12,((1+Assumptions!$D$26)^12-1)/Assumptions!$D$26) -> 3.2570277e+08 | I10: =Assumptions!$B$16*(C10*IF(Assumptions!$B$26=0,12,((1+Assumptions!$B$26)^12-1)/Assumptions!$B$26)+E10*IF(Assumptions!$C$26=0,12,((1+Assumptions!$C$26)^12-1)/Assumptions!$C$26)+G10*IF(Assumptions!$D$26=0,12,((1+Assumptions!$D$26)^12-1)/Assumptions!$D$26))+Assumptions!$B$17*(C10*(1+Assumptions!$B$26)^11+E10*(1+Assumptions!$C$26)^11+G10*(1+Assumptions!$D$26)^11)+Assumptions!$B$11*12 -> 68957036 | J10: =H10-I10 -> 2.5674573e+08 | K10: =IF(H10=0,0,J10/H10) -> 0.78828231
A11: 0.1 | B11: =Assumptions!B20*(1+A11) -> 4398.9 | C11: =Assumptions!B25*(1+(A11/0.1)*Assumptions!B30) -> 1080 | D11: =Assumptions!B21*(1+A11) -> 8798.9 | E11: =Assumptions!C25*(1+(A11/0.1)*Assumptions!C30) -> 760 | F11: =Assumptions!B22*(1+A11) -> 16498.9 | G11: =Assumptions!D25*(1+(A11/0.1)*Assumptions!D30) -> 390 | H11: =C11*B11*IF(Assumptions!$B$26=0,12,((1+Assumptions!$B$26)^12-1)/Assumptions!$B$26)+E11*D11*IF(Assumptions!$C$26=0,12,((1+Assumptions!$C$26)^12-1)/Assumptions!$C$26)+G11*F11*IF(Assumptions!$D$26=0,12,((1+Assumptions!$D$26)^12-1)/Assumptions!$D$26) -> 3.3091575e+08 | I11: =Assumptions!$B$16*(C11*IF(Assumptions!$B$26=0,12,((1+Assumptions!$B$26)^12-1)/Assumptions!$B$26)+E11*IF(Assumptions!$C$26=0,12,((1+Assumptions!$C$26)^12-1)/Assumptions!$C$26)+G11*IF(Assumptions!$D$26=0,12,((1+Assumptions!$D$26)^12-1)/Assumptions!$D$26))+Assumptions!$B$17*(C11*(1+Assumptions!$B$26)^11+E11*(1+Assumptions!$C$26)^11+G11*(1+Assumptions!$D$26)^11)+Assumptions!$B$11*12 -> 66317463 | J11: =H11-I11 -> 2.6459829e+08 | K11: =IF(H11=0,0,J11/H11) -> 0.79959412
A12: 0.15 | B12: =Assumptions!B20*(1+A12) -> 4598.85 | C12: =Assumptions!B25*(1+(A12/0.1)*Assumptions!B30) -> 1020 | D12: =Assumptions!B21*(1+A12) -> 9198.85 | E12: =Assumptions!C25*(1+(A12/0.1)*Assumptions!C30) -> 740 | F12: =Assumptions!B22*(1+A12) -> 17248.85 | G12: =Assumptions!D25*(1+(A12/0.1)*Assumptions!D30) -> 385 | H12: =C12*B12*IF(Assumptions!$B$26=0,12,((1+Assumptions!$B$26)^12-1)/Assumptions!$B$26)+E12*D12*IF(Assumptions!$C$26=0,12,((1+Assumptions!$C$26)^12-1)/Assumptions!$C$26)+G12*F12*IF(Assumptions!$D$26=0,12,((1+Assumptions!$D$26)^12-1)/Assumptions!$D$26) -> 3.3519267e+08 | I12: =Assumptions!$B$16*(C12*IF(Assumptions!$B$26=0,12,((1+Assumptions!$B$26)^12-1)/Assumptions!$B$26)+E12*IF(Assumptions!$C$26=0,12,((1+Assumptions!$C$26)^12-1)/Assumptions!$C$26)+G12*IF(Assumptions!$D$26=0,12,((1+Assumptions!$D$26)^12-1)/Assumptions!$D$26))+Assumptions!$B$17*(C12*(1+Assumptions!$B$26)^11+E12*(1+Assumptions!$C$26)^11+G12*(1+Assumptions!$D$26)^11)+Assumptions!$B$11*12 -> 63677890 | J12: =H12-I12 -> 2.7151478e+08 | K12: =IF(H12=0,0,J12/H12) -> 0.81002601
A13: 0.2 | B13: =Assumptions!B20*(1+A13) -> 4798.8 | C13: =Assumptions!B25*(1+(A13/0.1)*Assumptions!B30) -> 960 | D13: =Assumptions!B21*(1+A13) -> 9598.8 | E13: =Assumptions!C25*(1+(A13/0.1)*Assumptions!C30) -> 720 | F13: =Assumptions!B22*(1+A13) -> 17998.8 | G13: =Assumptions!D25*(1+(A13/0.1)*Assumptions!D30) -> 380 | H13: =C13*B13*IF(Assumptions!$B$26=0,12,((1+Assumptions!$B$26)^12-1)/Assumptions!$B$26)+E13*D13*IF(Assumptions!$C$26=0,12,((1+Assumptions!$C$26)^12-1)/Assumptions!$C$26)+G13*F13*IF(Assumptions!$D$26=0,12,((1+Assumptions!$D$26)^12-1)/Assumptions!$D$26) -> 3.3853353e+08 | I13: =Assumptions!$B$16*(C13*IF(Assumptions!$B$26=0,12,((1+Assumptions!$B$26)^12-1)/Assumptions!$B$26)+E13*IF(Assumptions!$C$26=0,12,((1+Assumptions!$C$26)^12-1)/Assumptions!$C$26)+G13*IF(Assumptions!$D$26=0,12,((1+Assumptions!$D$26)^12-1)/Assumptions!$D$26))+Assumptions!$B$17*(C13*(1+Assumptions!$B$26)^11+E13*(1+Assumptions!$C$26)^11+G13*(1+Assumptions!$D$26)^11)+Assumptions!$B$11*12 -> 61038317 | J13: =H13-I13 -> 2.7749522e+08 | K13: =IF(H13=0,0,J13/H13) -> 0.81969787
A14: 0.25 | B14: =Assumptions!B20*(1+A14) -> 4998.75 | C14: =Assumptions!B25*(1+(A14/0.1)*Assumptions!B30) -> 900 | D14: =Assumptions!B21*(1+A14) -> 9998.75 | E14: =Assumptions!C25*(1+(A14/0.1)*Assumptions!C30) -> 700 | F14: =Assumptions!B22*(1+A14) -> 18748.75 | G14: =Assumptions!D25*(1+(A14/0.1)*Assumptions!D30) -> 375 | H14: =C14*B14*IF(Assumptions!$B$26=0,12,((1+Assumptions!$B$26)^12-1)/Assumptions!$B$26)+E14*D14*IF(Assumptions!$C$26=0,12,((1+Assumptions!$C$26)^12-1)/Assumptions!$C$26)+G14*F14*IF(Assumptions!$D$26=0,12,((1+Assumptions!$D$26)^12-1)/Assumptions!$D$26) -> 3.4093833e+08 | I14: =Assumptions!$B$16*(C14*IF(Assumptions!$B$26=0,12,((1+Assumptions!$B$26)^12-1)/Assumptions!$B$26)+E14*IF(Assumptions!$C$26=0,12,((1+Assumptions!$C$26)^12-1)/Assumptions!$C$26)+G14*IF(Assumptions!$D$26=0,12,((1+Assumptions!$D$26)^12-1)/Assumptions!$D$26))+Assumptions!$B$17*(C14*(1+Assumptions!$B$26)^11+E14*(1+Assumptions!$C$26)^11+G14*(1+Assumptions!$D$26)^11)+Assumptions!$B$11*12 -> 58398744 | J14: =H14-I14 -> 2.8253959e+08 | K14: =IF(H14=0,0,J14/H14) -> 0.82871171
A15: 0.3 | B15: =Assumptions!B20*(1+A15) -> 5198.7 | C15: =Assumptions!B25*(1+(A15/0.1)*Assumptions!B30) -> 840 | D15: =Assumptions!B21*(1+A15) -> 10398.7 | E15: =Assumptions!C25*(1+(A15/0.1)*Assumptions!C30) -> 680 | F15: =Assumptions!B22*(1+A15) -> 19498.7 | G15: =Assumptions!D25*(1+(A15/0.1)*Assumptions!D30) -> 370 | H15: =C15*B15*IF(Assumptions!$B$26=0,12,((1+Assumptions!$B$26)^12-1)/Assumptions!$B$26)+E15*D15*IF(Assumptions!$C$26=0,12,((1+Assumptions!$C$26)^12-1)/Assumptions!$C$26)+G15*F15*IF(Assumptions!$D$26=0,12,((1+Assumptions!$D$26)^12-1)/Assumptions!$D$26) -> 3.4240707e+08 | I15: =Assumptions!$B$16*(C15*IF(Assumptions!$B$26=0,12,((1+Assumptions!$B$26)^12-1)/Assumptions!$B$26)+E15*IF(Assumptions!$C$26=0,12,((1+Assumptions!$C$26)^12-1)/Assumptions!$C$26)+G15*IF(Assumptions!$D$26=0,12,((1+Assumptions!$D$26)^12-1)/Assumptions!$D$26))+Assumptions!$B$17*(C15*(1+Assumptions!$B$26)^11+E15*(1+Assumptions!$C$26)^11+G15*(1+Assumptions!$D$26)^11)+Assumptions!$B$11*12 -> 55759171 | J15: =H15-I15 -> 2.866479e+08 | K15: =IF(H15=0,0,J15/H15) -> 0.83715532

Sheet Breakeven Analysis
A1: Breakeven & Cumulative Profitability Analysis
A2: Tracks when CustomerPulse AI surpasses opportunity cost
A4: Month | B4: Month 1 | C4: Month 2 | D4: Month 3 | E4: Month 4 | F4: Month 5 | G4: Month 6 | H4: Month 7 | I4: Month 8 | J4: Month 9 | K4: Month 10 | L4: Month 11 | M4: Month 12
A5: Monthly Gross Profit (Rs.) | B5: ='Monthly Model'!B46 -> 8459266.7 | C5: ='Monthly Model'!C46 -> 14831563 | D5: ='Monthly Model'!D46 -> 15916816 | E5: ='Monthly Model'!E46 -> 17087075 | F5: ='Monthly Model'!F46 -> 18349392 | G5: ='Monthly Model'!G46 -> 19711428 | H5: ='Monthly Model'!H46 -> 21181507 | I5: ='Monthly Model'!I46 -> 22768680 | ... M5: ='Monthly Model'!M46 -> 30498509
A6: Cumulative Profit (Rs.) | B6: =B5 -> 8459266.7 | C6: =B6+C5 -> 23290829 | D6: =C6+D5 -> 39207645 | E6: =D6+E5 -> 56294720 | F6: =E6+F5 -> 74644113 | G6: =F6+G5 -> 94355540 | H6: =G6+H5 -> 1.1553705e+08 | I6: =H6+I5 -> 1.3830573e+08 | J6: =I6+J5 -> 1.6278852e+08 | ... M6: =L6+M5 -> 2.4795711e+08
A7: Total Investment (Rs.) | B7: =Assumptions!B5+Assumptions!B6 -> 1800000 | C7: =Assumptions!B5+Assumptions!B6 -> 1800000 | D7: =Assumptions!B5+Assumptions!B6 -> 1800000 | E7: =Assumptions!B5+Assumptions!B6 -> 1800000 | F7: =Assumptions!B5+Assumptions!B6 -> 1800000 | G7: =Assumptions!B5+Assumptions!B6 -> 1800000 | H7: =Assumptions!B5+Assumptions!B6 -> 1800000 | I7: =Assumptions!B5+Assumptions!B6 -> 1800000 | J7: =Assumptions!B5+Assumptions!B6 -> 1800000 | K7: =Assumptions!B5+Assumptions!B6 -> 1800000 | L7: =Assumptions!B5+Assumptions!B6 -> 1800000 | M7: =Assumptions!B5+Assumptions!B6 -> 1800000
A8: Opportunity Cost (Rs.) | B8: =Assumptions!$B$38 -> 2500000 | C8: =Assumptions!$B$38 -> 2500000 | D8: =Assumptions!$B$38 -> 2500000 | E8: =Assumptions!$B$38 -> 2500000 | F8: =Assumptions!$B$38 -> 2500000 | G8: =Assumptions!$B$38 -> 2500000 | H8: =Assumptions!$B$38 -> 2500000 | I8: =Assumptions!$B$38 -> 2500000 | ... M8: =Assumptions!$B$38 -> 2500000
A9: Investment + Opportunity Cost (Rs.) | B9: =B7+B8 -> 4300000 | C9: =C7+C8 -> 4300000 | D9: =D7+D8 -> 4300000 | E9: =E7+E8 -> 4300000 | F9: =F7+F8 -> 4300000 | G9: =G7+G8 -> 4300000 | H9: =H7+H8 -> 4300000 | I9: =I7+I8 -> 4300000 | ... M9: =M7+M8 -> 4300000
A10: Cumulative Profit − Total Hurdle | B10: =B6-B9 -> 4159266.7 | C10: =C6-C9 -> 18990829 | D10: =D6-D9 -> 34907645 | E10: =E6-E9 -> 51994720 | F10: =F6-F9 -> 70344113 | G10: =G6-G9 -> 90055540 | H10: =H6-H9 -> 1.1123705e+08 | I10: =I6-I9 -> 1.3400573e+08 | ... M10: =M6-M9 -> 2.4365711e+08
A11: Breakeven Achieved? | B11: =IF(B10>=0,"YES","NO") -> YES | C11: =IF(C10>=0,"YES","NO") -> YES | D11: =IF(D10>=0,"YES","NO") -> YES | E11: =IF(E10>=0,"YES","NO") -> YES | F11: =IF(F10>=0,"YES","NO") -> YES | G11: =IF(G10>=0,"YES","NO") -> YES | H11: =IF(H10>=0,"YES","NO") -> YES | I11: =IF(I10>=0,"YES","NO") -> YES | ... M11: =IF(M10>=0,"YES","NO") -> YES
A13: KEY METRICS SUMMARY
A14: Total 12-Month Revenue (Rs.) | B14: =SUM('Monthly Model'!B41:M41) -> 3.1955372e+08
A15: Total 12-Month Cost (Rs.) | B15: =SUM('Monthly Model'!B45:M45) -> 71596609
A16: Total 12-Month Profit (Rs.) | B16: =B14-B15 -> 2.4795711e+08
A17: Overall Profit Margin (%) | B17: =IF(B14=0,0,B16/B14) -> 0.77594813
A18: ROI vs Investment (%) | B18: =IF(B7=0,0,B16/B7) -> 137.75395
A19: ROI vs Opportunity Cost (%) | B19: =IF(B8=0,0,B16/B8) -> 99.182845
A20: Month-12 Total Subscribers | B20: ='Monthly Model'!M39 -> 5973.187
A21: Month-12 Monthly Recurring Revenue | B21: ='Monthly Model'!M41 -> 38873513

Sheet Charts
A1: CustomerPulse AI — Financial Model Visualizations

Sheet Insights & Recommendations
A1: Strategic Insights & Recommendations
A2: Marketing Analyst — Orbitel CustomerPulse AI
A4: 1. FINANCIAL VIABILITY ASSESSMENT
A5: The base-case model projects strong profitability from Month 1 itself, driven by the large subscriber base across
A6: all three tiers. With 1,200 Starter, 800 Growth, and 400 Pro clients at launch, the combined monthly revenue
A7: significantly exceeds operating costs. The 12-month cumulative profit is expected to far exceed both the initial
A8: investment (Rs. 1.8M) and the total opportunity cost (Rs. 2.5M), confirming financial viability.
A10: 2. KEY DRIVERS OF PROFITABILITY
A11: Pro Tier is the margin leader: Despite having the smallest subscriber base, Pro contributes disproportionately
A12: to revenue at Rs. 14,999/month per client. Its margin exceeds 80% due to the premium pricing.
A13: Starter Tier drives volume: The 10% monthly growth rate on Starter generates the fastest subscriber expansion,
A14: compounding to over 3x the initial base by Month 12.
... A52: the trajectory deviates from plan.
